Workbook

Sheet data_use
A1: santa cruz mountains long term forest monitoring network
A2: version: jan162026
A3: intended use
A4: These data are being shared for the following purpose: -Shive fuels project data exploration/project planning/collaborative research in redwoods Use of the data for purposes beyond this scope should be discussed with the SCMLTFMN team prior to proceeding.
A5: collaboration and privacy expectations
A6: The SCMLTFMN is a collaborative monitoring network built through partnerships across agencies, landowners, and organizations. -Please coordinate with the SCMLTFMN team before using the data in reports, presentations, or publications. -Multiple researchers and affiliates are actively using SCMLTFMN data for ongoing projects. To avoid overlap, please limit your use to the intended purpose described above and check with the SCMLTFMN team before expanding into new analyses or topics. -Plot locations are NOT public. -Please acknowledge the SCMLTFMN and funding sources in any resulting products.
A7: data sharing
A8: To maintain data integrity and respect partner contributions: -These data are shared as part of an active, ongoing monitoring network and are not considered public-release datasets. -Please do not redistribute the raw dataset outside your immediate project team. -If others are interested in the data, connect them with the SCMLTFMN team so we can provide the most current version and context.
A9: disclaimer
A10: While every effort has been made to ensure the accuracy of these data, errors and omissions may occur. The data are provided “as is” without warranty of any kind, either expressed or implied.
A11: No warranty is made regarding their completeness or suitability for any specific use.
A12: contact
... A16: 831-348-7305

Sheet field_metadata
A1: This spreadhseet describes the summary variables that exist in the "plot_master" datasheet.
A2: field_name | B2: category | C2: data_type | D2: units | E2: description | F2: method
A3: plot_name | B3: Plot ID | C3: text | D3: none | E3: Unique plot identifier | F3: Assigned ID
A4: plot_mark | B4: Plot ID | C4: text | D4: none | E4: Physical marker type at plot center | F4: Field observation
A5: latitude | B5: Location | C5: decimal | D5: degrees | E5: Plot center latitude (WGS84) | F5: GPS receiver (±2m accuracy whenever possible)
A6: longitude | B6: Location | C6: decimal | D6: degrees | E6: Plot center longitude (WGS84) | F6: GPS receiver (±2m accuracy whenever possible)
A7: insta# | B7: Photos | C7: integer | D7: none | E7: Insta360 photo sequence number | F7: Recorded in Survey123
A8: insta360_filename | B8: Photos | C8: text | D8: none | E8: Filename of 360° panorama (e.g., 2025-05-21 10:04) | F8: Insta360 ONE X2 camera app - for internal use
A9: czu_dnbr | B9: Fire | C9: integer | D9: dNBR units | E9: CZU Lightning Complex (2020) differenced Normalized Burn Ratio | F9: Monitoring Trends in Burn Severity
A10: burn_scars_anytime | B10: Fire | C10: boolean | D10: yes/no | E10: Evidence of fire at any time in plot history (burn scars, etc) | F10: Field observation
A11: lockheed | B11: Management | C11: boolean | D11: yes/no | E11: Within Lockheed Fire footprint | F11: Monitoring Trends in Burn Severity fire footprint
A12: site_masticated | B12: Management | C12: boolean | D12: yes/no | E12: Plot in masticated/chipped fuel treatment area | F12: Field observation
A13: veg_type | B13: Vegetation | C13: text | D13: none | E13: Dominant vegetation type | F13: Vegetation data
... A175: qmd_dead_Hardwoods | B175: Size | C175: decimal | D175: cm | E175: Hardwood quadratic mean diameter - dead trees | F175: Calculated: sqrt((BA/TPA)/0.005454)*2.54, NA if TPA=0

Sheet plots_master
A1: plot_name | B1: plot_mark | C1: lockheed | D1: czu_dnbr | E1: burn_scars_anytime | F1: latitude | G1: longitude | H1: insta# | I1: insta360_filename | J1: site_masticated | K1: veg_type | L1: sese_seedlings | M1: psme_seedlings | N1: California black oak | O1: MIN_plot_height_ft | P1: MAX_tree_height_ft | Q1: MEAN_height_ft | R1: sky | S1: canopycover_all | T1: canopycover_live | U1: canopycover_dead | V1: psme_dead_canopy | W1: psme_live_canopy | X1: hardwood_dead_canopy | Y1: hardwood_live_canopy | Z1: redwood_dead_canopy | AA1: redwood_live_canopy | AB1: sky | AC1: canopycover_all | AD1: canopycover_live | AE1: canopycover_dead | AF1: ceanothus_cover | AG1: ceanothus_height_m | AH1: avg_shrub_pct | AI1: avg_noshrub_pct | AJ1: firemon_height_all_shrubs_m | AK1: mgha_1h_mean | AL1: mgha_10h_mean | AM1: mgha_100h_mean | AN1: mgha_fine_mean | AO1: mgha_1000s_mean | AP1: mgha_1000r_mean | AQ1: mgha_1000_mean | AR1: mgha_coarse_mean | AS1: mgha_total_mean | AT1: mean_duff_depth_cm | AU1: mean_litter_depth_cm | AV1: total_tpa | AW1: live_tpa | AX1: dead_tpa | AY1: pct_dead_count | AZ1: total_ba_acre | BA1: live_ba_acre | BB1: dead_ba_acre | BC1: pct_dead_ba | BD1: qmd_total_cm | BE1: qmd_live_cm | BF1: qmd_dead_cm | BG1: pct_dead_count_Douglas-fir | BH1: pct_dead_count_Redwood | BI1: pct_dead_count_Tanoak | BJ1: pct_dead_count_Other_Quercus | BK1: pct_dead_count_Madrone | BL1: pct_dead_count_Other | BM1: pct_dead_count_Bay_laurel | BN1: pct_dead_count_Black_oak | BO1: pct_dead_ba_Douglas-fir | BP1: pct_dead_ba_Redwood | BQ1: pct_dead_ba_Tanoak | BR1: pct_dead_ba_Other_Quercus | BS1: pct_dead_ba_Madrone | BT1: pct_dead_ba_Other | BU1: pct_dead_ba_Bay_laurel | BV1: pct_dead_ba_Black_oak | BW1: tpa_Douglas-fir | BX1: tpa_Redwood | BY1: tpa_Tanoak | BZ1: tpa_Other_Quercus | CA1: tpa_Madrone | CB1: tpa_Other | CC1: tpa_Bay_laurel | CD1: tpa_Black_oak | CE1: live_tpa_Douglas-fir | CF1: live_tpa_Redwood | CG1: live_tpa_Tanoak | CH1: live_tpa_Other_Quercus | CI1: live_tpa_Madrone | CJ1: live_tpa_Other | CK1: live_tpa_Bay_laurel | CL1: live_tpa_Black_oak | CM1: dead_tpa_Douglas-fir | CN1: dead_tpa_Redwood | CO1: dead_tpa_Tanoak | CP1: dead_tpa_Other_Quercus | CQ1: dead_tpa_Madrone | CR1: dead_tpa_Other | CS1: dead_tpa_Bay_laurel | CT1: dead_tpa_Black_oak | CU1: ba_acre_total_Douglas-fir | CV1: ba_acre_total_Redwood | CW1: ba_acre_total_Tanoak | CX1: ba_acre_total_Other_Quercus | CY1: ba_acre_total_Madrone | CZ1: ba_acre_total_Other | DA1: ba_acre_total_Bay_laurel | DB1: ba_acre_total_Black_oak | DC1: ba_acre_live_Douglas-fir | DD1: ba_acre_live_Redwood | DE1: ba_acre_live_Tanoak | DF1: ba_acre_live_Other_Quercus | DG1: ba_acre_live_Madrone | DH1: ba_acre_live_Other | DI1: ba_acre_live_Bay_laurel | DJ1: ba_acre_live_Black_oak | DK1: ba_acre_dead_Douglas-fir | DL1: ba_acre_dead_Redwood | DM1: ba_acre_dead_Tanoak | DN1: ba_acre_dead_Other_Quercus | DO1: ba_acre_dead_Madrone | DP1: ba_acre_dead_Other | DQ1: ba_acre_dead_Bay_laurel | DR1: ba_acre_dead_Black_oak | DS1: qmd_total_Douglas-fir | DT1: qmd_total_Redwood | DU1: qmd_total_Tanoak | DV1: qmd_total_Other_Quercus | DW1: qmd_total_Madrone | DX1: qmd_total_Other | DY1: qmd_total_Bay_laurel | DZ1: qmd_total_Black_oak | EA1: qmd_live_Douglas-fir | EB1: qmd_live_Redwood | EC1: qmd_live_Tanoak | ED1: qmd_live_Other_Quercus | EE1: qmd_live_Madrone | EF1: qmd_live_Other | EG1: qmd_live_Bay_laurel | EH1: qmd_live_Black_oak | EI1: qmd_dead_Douglas-fir | EJ1: qmd_dead_Redwood | EK1: qmd_dead_Tanoak | EL1: qmd_dead_Other_Quercus | EM1: qmd_dead_Madrone | EN1: qmd_dead_Other | EO1: qmd_dead_Bay_laurel | EP1: qmd_dead_Black_oak | EQ1: Hardwoods_tpa | ER1: Hardwoods_live_tpa | ES1: Hardwoods_dead_tpa | ET1: Hardwoods_ba_acre | EU1: Hardwoods_ba_acre_live | EV1: Hardwoods_ba_acre_dead | EW1: Hardwoods_pct_dead_count | EX1: Hardwoods_pct_dead_ba | EY1: qmd_total_Hardwoods | EZ1: qmd_live_Hardwoods | FA1: qmd_dead_Hardwoods | FB1: large_>30cm_pct_dead_count | FC1: medium_10-30cm_pct_dead_count | FD1: large_>30cm_tpa | FE1: medium_10-30cm_tpa | FF1: sapling_tpa | FG1: sapling_live_tpa | FH1: sapling_dead_tpa | FI1: sapling_pct_dead | FJ1: qmd_Douglas-fir_live_cm | FK1: qmd_Redwood_live_cm | FL1: qmd_Tanoak_live_cm | FM1: qmd_Other_Quercus_live_cm | FN1: qmd_Madrone_live_cm | FO1: qmd_Other_live_cm | FP1: qmd_Bay_laurel_live_cm | FQ1: qmd_Black_oak_live_cm | FR1: pct_epicormic | FS1: pct_basal_sprout | FT1: pct_broken_top | FU1: pct_hollow
A2: BB1 | B2: Stake | C2: UNBURNED | D2: 698 | E2: Yes | F2: 37.202489415 | G2: -122.25358118833334 | H2: 1 | I2: 2025-07-01 16:14 | J2: No | K2: SESE | L2: 0 | M2: 0 | N2: 0 | O2: 0 | P2: 171.45 | Q2: 74.294711 | R2: 0.46341463 | S2: 0.53658537 | T2: 0.53658537 | U2: 0 | V2: 0 | W2: 0.48780488 | X2: 0 | Y2: 0 | Z2: 0 | AA2: 0.048780488 | AB2: 0.46341463 | AC2: 0.53658537 | AD2: 0.53658537 | AE2: 0 | AF2: =_xlfn.XLOOKUP(A2, ceanothus_cover!$A:$A, ceanothus_cover!$D:$D, "") -> 70.79646 | AG2: =_xlfn.XLOOKUP(A2, ceanothus_cover!$A:$A, ceanothus_cover!$E:$E, "") -> 3.5043777 | AH2: 78.318584 | AI2: 21.681416 | AJ2: 3.2771812 | AK2: 0.47225923 | AL2: 3.1167599 | AM2: 9.9218656 | AN2: 13.510885 | AO2: 81.536683 | AP2: 0 | AQ2: 81.536683 | AR2: 81.536683 | AS2: 95.047568 | AT2: 1 | AU2: 1.875 | AV2: 80 | AW2: 40 | AX2: 40 | AY2: 50 | AZ2: 202.01213 | BA2: 181.51973 | BB2: 20.492402 | BC2: 10.144144 | BD2: 54.65374 | BE2: 73.266943 | BF2: 24.617423 | BG2: 50 | BH2: 0 | BI2: 66.666667 | BJ2: NA | BK2: NA | BL2: NA | BM2: NA | BN2: NA | BO2: 6.7280792 | BP2: 0 | BQ2: 43.416087 | BR2: NA | BS2: NA | BT2: NA | BU2: NA | BV2: NA | BW2: 40 | BX2: 10 | BY2: 30 | BZ2: 0 | CA2: 0 | CB2: 0 | CC2: 0 | CD2: 0 | CE2: 20 | CF2: 10 | CG2: 10 | CH2: 0 | CI2: 0 | CJ2: 0 | CK2: 0 | CL2: 0 | CM2: 20 | CN2: 0 | CO2: 20 | CP2: 0 | CQ2: 0 | CR2: 0 | CS2: 0 | CT2: 0 | CU2: 169.72823 | CV2: 11.386227 | CW2: 20.897673 | CX2: 0 | CY2: 0 | CZ2: 0 | DA2: 0 | DB2: 0 | DC2: 158.30878 | DD2: 11.386227 | DE2: 11.824721 | DF2: 0 | DG2: 0 | DH2: 0 | DI2: 0 | DJ2: 0 | DK2: 11.41945 | DL2: 0 | DM2: 9.0729517 | DN2: 0 | DO2: 0 | DP2: 0 | DQ2: 0 | DR2: 0 | DS2: 70.847283 | DT2: 36.7 | DU2: 28.705458 | DV2: NA | DW2: NA | DX2: NA | DY2: NA | DZ2: NA | EA2: 96.763965 | EB2: 36.7 | EC2: 37.4 | ED2: NA | EE2: NA | EF2: NA | EG2: NA | EH2: NA | EI2: 25.988651 | EJ2: NA | EK2: 23.165168 | EL2: NA | EM2: NA | EN2: NA | EO2: NA | EP2: NA | EQ2: 30 | ER2: 10 | ES2: 20 | ET2: 20.897673 | EU2: 11.824721 | EV2: 9.0729517 | EW2: 66.666667 | EX2: 43.416087 | EY2: 28.705458 | EZ2: 37.4 | FA2: 23.165168 | FB2: 20 | FC2: 100 | FD2: 50 | FE2: 30 | FF2: 0 | FG2: 0 | FH2: 0 | FI2: NA | FJ2: 96.763965 | FK2: 36.7 | FL2: 37.4 | FM2: NA | FN2: NA | FO2: NA | FP2: NA | FQ2: NA | FR2: 12.5 | FS2: 100 | FT2: 0 | FU2: 0
A3: BB10 | B3: Rebar | C3: UNBURNED | D3: 249 | E3: Yes | F3: 37.195288945 | G3: -122.25956996166666 | H3: 2 | I3: 2025-07-16 09:40 | J3: No | K3: SESE | L3: 5 | M3: 6 | N3: 0 | O3: 0 | P3: 135.75999 | Q3: 81.941533 | R3: 0.027272727 | S3: 0.97272727 | T3: 0.90909091 | U3: 0.063636364 | V3: 0 | W3: 0.14545455 | X3: 0.063636364 | Y3: 0 | Z3: 0 | AA3: 0.76363636 | AB3: 0.027272727 | AC3: 0.97272727 | AD3: 0.90909091 | AE3: 0.063636364 | AF3: =_xlfn.XLOOKUP(A3, ceanothus_cover!$A:$A, ceanothus_cover!$D:$D, "") -> 0.13274336 | AG3: =_xlfn.XLOOKUP(A3, ceanothus_cover!$A:$A, ceanothus_cover!$E:$E, "") -> 0.3 | AH3: 4.4911504 | AI3: 95.50885 | AJ3: 1.4808271 | AK3: 1.2702145 | AL3: 4.0517879 | AM3: 12.402332 | AN3: 17.724334 | AO3: 16.439122 | AP3: 0 | AQ3: 16.439122 | AR3: 16.439122 | AS3: 34.163456 | AT3: 6.75 | AU3: 1.5 | AV3: 140 | AW3: 100 | AX3: 40 | AY3: 28.571429 | AZ3: 314.79072 | BA3: 288.08737 | BB3: 26.703347 | BC3: 8.482889 | BD3: 51.573083 | BE3: 58.376528 | BF3: 28.101468 | BG3: 0 | BH3: 0 | BI3: 80 | BJ3: NA | BK3: NA | BL3: NA | BM3: NA | BN3: NA | BO3: 0 | BP3: 0 | BQ3: 71.481233 | BR3: NA | BS3: NA | BT3: NA | BU3: NA | BV3: NA | BW3: 10 | BX3: 80 | BY3: 50 | BZ3: 0 | CA3: 0 | CB3: 0 | CC3: 0 | CD3: 0 | CE3: 10 | CF3: 80 | CG3: 10 | CH3: 0 | CI3: 0 | CJ3: 0 | CK3: 0 | CL3: 0 | CM3: 0 | CN3: 0 | CO3: 40 | CP3: 0 | CQ3: 0 | CR3: 0 | CS3: 0 | CT3: 0 | CU3: 22.247562 | CV3: 255.18601 | CW3: 37.357144 | CX3: 0 | CY3: 0 | CZ3: 0 | DA3: 0 | DB3: 0 | DC3: 22.247562 | DD3: 255.18601 | DE3: 10.653797 | DF3: 0 | DG3: 0 | DH3: 0 | DI3: 0 | DJ3: 0 | DK3: 0 | DL3: 0 | DM3: 26.703347 | DN3: 0 | DO3: 0 | DP3: 0 | DQ3: 0 | DR3: 0 | DS3: 51.3 | DT3: 61.42704 | DU3: 29.728841 | DV3: NA | DW3: NA | DX3: NA | DY3: NA | DZ3: NA | EA3: 51.3 | EB3: 61.42704 | EC3: 35.5 | ED3: NA | EE3: NA | EF3: NA | EG3: NA | EH3: NA | EI3: NA | EJ3: NA | EK3: 28.101468 | EL3: NA | EM3: NA | EN3: NA | EO3: NA | EP3: NA | EQ3: 50 | ER3: 10 | ES3: 40 | ET3: 37.357144 | EU3: 10.653797 | EV3: 26.703347 | EW3: 80 | EX3: 71.481233 | EY3: 29.728841 | EZ3: 35.5 | FA3: 28.101468 | FB3: 12.5 | FC3: 50 | FD3: 80 | FE3: 60 | FF3: 0 | FG3: 0 | FH3: 0 | FI3: NA | FJ3: 51.3 | FK3: 61.42704 | FL3: 35.5 | FM3: NA | FN3: NA | FO3: NA | FP3: NA | FQ3: NA | FR3: 0 | FS3: 92.857143 | FT3: 0 | FU3: 0
A4: BB11 | B4: Rebar | C4: UNBURNED | D4: 146 | E4: Yes | F4: 37.19708570375597 | G4: -122.24238071799124 | H4: 2 | I4: 2025-06-30 11:51 | J4: No | K4: SESE | L4: 0 | M4: 0 | N4: 0 | O4: 0.38 | P4: 153.00999 | Q4: 95.03162 | R4: 0.25252525 | S4: 0.74747475 | T4: 0.74747475 | U4: 0 | V4: 0 | W4: 0 | X4: 0 | Y4: 0.36363636 | Z4: 0 | AA4: 0.38383838 | AB4: 0.25252525 | AC4: 0.74747475 | AD4: 0.74747475 | AE4: 0 | AF4: 0 | AG4: NA | AH4: 8.6061947 | AI4: 91.393805 | AJ4: 0.77977642 | AK4: 0.81424006 | AL4: 2.181732 | AM4: 13.642565 | AN4: 16.638537 | AO4: 24.741594 | AP4: 0 | AQ4: 24.741594 | AR4: 24.741594 | AS4: 41.380131 | AT4: 0.625 | AU4: 3.25 | AV4: 60 | AW4: 40 | AX4: 20 | AY4: 33.333333 | AZ4: 81.053054 | BA4: 70.584901 | BB4: 10.468153 | BC4: 12.915186 | BD4: 39.9747 | BE4: 45.687991 | BF4: 24.882624 | BG4: NA | BH4: 33.333333 | BI4: 33.333333 | BJ4: NA | BK4: NA | BL4: NA | BM4: NA | BN4: NA | BO4: NA | BP4: 6.821778 | BQ4: 15.038183 | BR4: NA | BS4: NA | BT4: NA | BU4: NA | BV4: NA | BW4: 0 | BX4: 30 | BY4: 30 | BZ4: 0 | CA4: 0 | CB4: 0 | CC4: 0 | CD4: 0 | CE4: 0 | CF4: 20 | CG4: 20 | CH4: 0 | CI4: 0 | CJ4: 0 | CK4: 0 | CL4: 0 | CM4: 0 | CN4: 10 | CO4: 10 | CP4: 0 | CQ4: 0 | CR4: 0 | CS4: 0 | CT4: 0 | CU4: 0 | CV4: 20.9429 | CW4: 60.110154 | CX4: 0 | CY4: 0 | CZ4: 0 | DA4: 0 | DB4: 0 | DC4: 0 | DD4: 19.514222 | DE4: 51.070679 | DF4: 0 | DG4: 0 | DH4: 0 | DI4: 0 | DJ4: 0 | DK4: 0 | DL4: 1.4286782 | DM4: 9.039475 | DN4: 0 | DO4: 0 | DP4: 0 | DQ4: 0 | DR4: 0 | DS4: NA | DT4: 28.736504 | DU4: 48.684358 | DV4: NA | DW4: NA | DX4: NA | DY4: NA | DZ4: NA | EA4: NA | EB4: 33.973225 | EC4: 54.960031 | ED4: NA | EE4: NA | EF4: NA | EG4: NA | EH4: NA | EI4: NA | EJ4: 13 | EK4: 32.7 | EL4: NA | EM4: NA | EN4: NA | EO4: NA | EP4: NA | EQ4: 30 | ER4: 20 | ES4: 10 | ET4: 60.110154 | EU4: 51.070679 | EV4: 9.039475 | EW4: 33.333333 | EX4: 15.038183 | EY4: 48.684358 | EZ4: 54.960031 | FA4: 32.7 | FB4: 25 | FC4: 50 | FD4: 40 | FE4: 20 | FF4: 0 | FG4: 0 | FH4: 0 | FI4: NA | FJ4: NA | FK4: 33.973225 | FL4: 54.960031 | FM4: NA | FN4: NA | FO4: NA | FP4: NA | FQ4: NA | FR4: 0 | FS4: 100 | FT4: 0 | FU4: 0
A5: BB12 | B5: Stake | C5: UNBURNED | D5: 137 | E5: Yes | F5: 37.19801656794056 | G5: -122.24301275146432 | H5: 1 | I5: 2025-06-30 15:37 | J5: No | K5: SESE | L5: 0 | M5: 0 | N5: 0 | O5: 27.690001 | P5: 135.89 | Q5: 79.431346 | R5: 0.034782609 | S5: 0.96521739 | T5: 0.90434783 | U5: 0.060869565 | V5: 0 | W5: 0.034782609 | X5: 0.060869565 | Y5: 0.15652174 | Z5: 0 | AA5: 0.71304348 | AB5: 0.034782609 | AC5: 0.96521739 | AD5: 0.90434783 | AE5: 0.060869565 | AF5: 0 | AG5: NA | AH5: 4.4247788 | AI5: 95.575221 | AJ5: 0.561 | AK5: 0.47225923 | AL5: 1.246704 | AM5: 1.2402332 | AN5: 2.9591964 | AO5: 0 | AP5: 0 | AQ5: 0 | AR5: 0 | AS5: 2.9591964 | AT5: 2.625 | AU5: 2.25 | AV5: 140 | AW5: 140 | AX5: 0 | AY5: 0 | AZ5: 414.53824 | BA5: 414.53824 | BB5: 0 | BC5: 0 | BD5: 59.182653 | BE5: 59.182653 | BF5: NA | BG5: 0 | BH5: 0 | BI5: 0 | BJ5: NA | BK5: NA | BL5: NA | BM5: NA | BN5: NA | BO5: 0 | BP5: 0 | BQ5: 0 | BR5: NA | BS5: NA | BT5: NA | BU5: NA | BV5: NA | BW5: 10 | BX5: 120 | BY5: 10 | BZ5: 0 | CA5: 0 | CB5: 0 | CC5: 0 | CD5: 0 | CE5: 10 | CF5: 120 | CG5: 10 | CH5: 0 | CI5: 0 | CJ5: 0 | CK5: 0 | CL5: 0 | CM5: 0 | CN5: 0 | CO5: 0 | CP5: 0 | CQ5: 0 | CR5: 0 | CS5: 0 | CT5: 0 | CU5: 10.474493 | CV5: 399.59173 | CW5: 4.4720162 | CX5: 0 | CY5: 0 | CZ5: 0 | DA5: 0 | DB5: 0 | DC5: 10.474493 | DD5: 399.59173 | DE5: 4.4720162 | DF5: 0 | DG5: 0 | DH5: 0 | DI5: 0 | DJ5: 0 | DK5: 0 | DL5: 0 | DM5: 0 | DN5: 0 | DO5: 0 | DP5: 0 | DQ5: 0 | DR5: 0 | DS5: 35.2 | DT5: 62.761566 | DU5: 23 | DV5: NA | DW5: NA | DX5: NA | DY5: NA | DZ5: NA | EA5: 35.2 | EB5: 62.761566 | EC5: 23 | ED5: NA | EE5: NA | EF5: NA | EG5: NA | EH5: NA | EI5: NA | EJ5: NA | EK5: NA | EL5: NA | EM5: NA | EN5: NA | EO5: NA | EP5: NA | EQ5: 10 | ER5: 10 | ES5: 0 | ET5: 4.4720162 | EU5: 4.4720162 | EV5: 0 | EW5: 0 | EX5: 0 | EY5: 23 | EZ5: 23 | FA5: NA | FB5: 0 | FC5: 0 | FD5: 90 | FE5: 50 | FF5: 0 | FG5: 0 | FH5: 0 | FI5: NA | FJ5: 35.2 | FK5: 62.761566 | FL5: 23 | FM5: NA | FN5: NA | FO5: NA | FP5: NA | FQ5: NA | FR5: 28.571429 | FS5: 100 | FT5: 0 | FU5: 0
A6: BB15 | B6: Stake | C6: UNBURNED | D6: 456 | E6: No | F6: 37.19466281 | G6: -122.25074200166667 | H6: 1 | I6: 2025-07-02 12:34 | J6: No | K6: SESE | L6: 7 | M6: 0 | N6: 0 | O6: 0 | P6: 132.3 | Q6: 25.408252 | R6: 0.78571429 | S6: 0.21428571 | T6: 0.21428571 | U6: 0 | V6: 0 | W6: 0 | X6: 0 | Y6: 0 | Z6: 0 | AA6: 0.21428571 | AB6: 0.78571429 | AC6: 0.21428571 | AD6: 0.21428571 | AE6: 0 | AF6: =_xlfn.XLOOKUP(A6, ceanothus_cover!$A:$A, ceanothus_cover!$D:$D, "") -> 25.221239 | AG6: =_xlfn.XLOOKUP(A6, ceanothus_cover!$A:$A, ceanothus_cover!$E:$E, "") -> 2.4276289 | AH6: 29.09292 | AI6: 70.90708 | AJ6: 2.1804953 | AK6: 0.61882244 | AL6: 0.93502798 | AM6: 11.162099 | AN6: 12.715949 | AO6: 14.749478 | AP6: 0 | AQ6: 14.749478 | AR6: 14.749478 | AS6: 27.465427 | AT6: 1.125 | AU6: 1.125 | AV6: 10 | AW6: 0 | AX6: 10 | AY6: 100 | AZ6: 9.7724967 | BA6: 0 | BB6: 9.7724967 | BC6: 100 | BD6: 34 | BE6: NA | BF6: 34 | BG6: NA | BH6: NA | BI6: 100 | BJ6: NA | BK6: NA | BL6: NA | BM6: NA | BN6: NA | BO6: NA | BP6: NA | BQ6: 100 | BR6: NA | BS6: NA | BT6: NA | BU6: NA | BV6: NA | BW6: 0 | BX6: 0 | BY6: 10 | BZ6: 0 | CA6: 0 | CB6: 0 | CC6: 0 | CD6: 0 | CE6: 0 | CF6: 0 | CG6: 0 | CH6: 0 | CI6: 0 | CJ6: 0 | CK6: 0 | CL6: 0 | CM6: 0 | CN6: 0 | CO6: 10 | CP6: 0 | CQ6: 0 | CR6: 0 | CS6: 0 | CT6: 0 | CU6: 0 | CV6: 0 | CW6: 9.7724967 | CX6: 0 | CY6: 0 | CZ6: 0 | DA6: 0 | DB6: 0 | DC6: 0 | DD6: 0 | DE6: 0 | DF6: 0 | DG6: 0 | DH6: 0 | DI6: 0 | DJ6: 0 | DK6: 0 | DL6: 0 | DM6: 9.7724967 | DN6: 0 | DO6: 0 | DP6: 0 | DQ6: 0 | DR6: 0 | DS6: NA | DT6: NA | DU6: 34 | DV6: NA | DW6: NA | DX6: NA | DY6: NA | DZ6: NA | EA6: NA | EB6: NA | EC6: NA | ED6: NA | EE6: NA | EF6: NA | EG6: NA | EH6: NA | EI6: NA | EJ6: NA | EK6: 34 | EL6: NA | EM6: NA | EN6: NA | EO6: NA | EP6: NA | EQ6: 10 | ER6: 0 | ES6: 10 | ET6: 9.7724967 | EU6: 0 | EV6: 9.7724967 | EW6: 100 | EX6: 100 | EY6: 34 | EZ6: NA | FA6: 34 | FB6: 100 | FC6: NA | FD6: 10 | FE6: 0 | FF6: 300 | FG6: 300 | FH6: 0 | FI6: 0 | FJ6: NA | FK6: NA | FL6: NA | FM6: NA | FN6: NA | FO6: NA | FP6: NA | FQ6: NA | FR6: 0 | FS6: 0 | FT6: 0 | FU6: 0
A7: BB16 | B7: Stake | C7: UNBURNED | D7: 208 | E7: Yes | F7: 37.197469701500005 | G7: -122.25041281316665 | H7: 2 | I7: 2025-07-02 15:01 | J7: No | K7: SESE | L7: 1 | M7: 0 | N7: 0 | O7: 0 | P7: 140.81999 | Q7: 70.248652 | R7: 0.13684211 | S7: 0.86315789 | T7: 0.86315789 | U7: 0 | V7: 0 | W7: 0 | X7: 0 | Y7: 0.12631579 | Z7: 0 | AA7: 0.73684211 | AB7: 0.13684211 | AC7: 0.86315789 | AD7: 0.86315789 | AE7: 0 | AF7: 0 | AG7: NA | AH7: 8.4070796 | AI7: 91.59292 | AJ7: 0.20723684 | AK7: 0.61882244 | AL7: 4.3634639 | AM7: 2.4804664 | AN7: 7.4627528 | AO7: 14.749478 | AP7: 0 | AQ7: 14.749478 | AR7: 14.749478 | AS7: 22.21223 | AT7: 3.5 | AU7: 1.5 | AV7: 170 | AW7: 120 | AX7: 50 | AY7: 29.411765 | AZ7: 346.81475 | BA7: 313.21951 | BB7: 33.59524 | BC7: 9.6867968 | BD7: 49.124763 | BE7: 55.566102 | BF7: 28.192268 | BG7: NA | BH7: 14.285714 | BI7: 100 | BJ7: NA | BK7: NA | BL7: NA | BM7: NA | BN7: NA | BO7: NA | BP7: 3.5391615 | BQ7: 100 | BR7: NA | BS7: NA | BT7: NA | BU7: NA | BV7: NA | BW7: 0 | BX7: 140 | BY7: 30 | BZ7: 0 | CA7: 0 | CB7: 0 | CC7: 0 | CD7: 0 | CE7: 0 | CF7: 120 | CG7: 0 | CH7: 0 | CI7: 0 | CJ7: 0 | CK7: 0 | CL7: 0 | CM7: 0 | CN7: 20 | CO7: 30 | CP7: 0 | CQ7: 0 | CR7: 0 | CS7: 0 | CT7: 0 | CU7: 0 | CV7: 324.71158 | CW7: 22.103173 | CX7: 0 | CY7: 0 | CZ7: 0 | DA7: 0 | DB7: 0 | DC7: 0 | DD7: 313.21951 | DE7: 0 | DF7: 0 | DG7: 0 | DH7: 0 | DI7: 0 | DJ7: 0 | DK7: 0 | DL7: 11.492067 | DM7: 22.103173 | DN7: 0 | DO7: 0 | DP7: 0 | DQ7: 0 | DR7: 0 | DS7: NA | DT7: 52.37946 | DU7: 29.5218 | DV7: NA | DW7: NA | DX7: NA | DY7: NA | DZ7: NA | EA7: NA | EB7: 55.566102 | EC7: NA | ED7: NA | EE7: NA | EF7: NA | EG7: NA | EH7: NA | EI7: NA | EJ7: 26.071153 | EK7: 29.5218 | EL7: NA | EM7: NA | EN7: NA | EO7: NA | EP7: NA | EQ7: 30 | ER7: 0 | ES7: 30 | ET7: 22.103173 | EU7: 0 | EV7: 22.103173 | EW7: 100 | EX7: 100 | EY7: 29.5218 | EZ7: NA | FA7: 29.5218 | FB7: 15.384615 | FC7: 75 | FD7: 130 | FE7: 40 | FF7: 0 | FG7: 0 | FH7: 0 | FI7: NA | FJ7: NA | FK7: 55.566102 | FL7: NA | FM7: NA | FN7: NA | FO7: NA | FP7: NA | FQ7: NA | FR7: 23.529412 | FS7: 94.117647 | FT7: 0 | FU7: 0
A8: BB17 | B8: Rebar | C8: UNBURNED | D8: 270 | E8: Yes | F8: 37.19995595500001 | G8: -122.25560555666668 | H8: 1 | I8: 2025-07-01 9:22 | J8: No | K8: SESE | L8: 1 | M8: 1 | N8: 0 | O8: 0 | P8: 123.68999 | Q8: 71.0622 | R8: 0.042253521 | S8: 0.95774648 | T8: 0.95774648 | U8: 0 | V8: 0 | W8: 0 | X8: 0 | Y8: 0.50704225 | Z8: 0 | AA8: 0.45070423 | AB8: 0.042253521 | AC8: 0.95774648 | AD8: 0.95774648 | AE8: 0 | AF8: 0 | AG8: NA | AH8: 15.752212 | AI8: 84.247788 | AJ8: 0.7325693 | AK8: 0.76538565 | AL8: 1.870056 | AM8: 1.2402332 | AN8: 3.8756748 | AO8: 12.654877 | AP8: 0 | AQ8: 12.654877 | AR8: 12.654877 | AS8: 16.530552 | AT8: 1.875 | AU8: 1.75 | AV8: 240 | AW8: 200 | AX8: 40 | AY8: 16.666667 | AZ8: 632.40337 | BA8: 626.75189 | BB8: 5.6514788 | BC8: 0.89365096 | BD8: 55.829999 | BE8: 60.884813 | BF8: 12.927877 | BG8: NA | BH8: 18.75 | BI8: 12.5 | BJ8: NA | BK8: NA | BL8: NA | BM8: NA | BN8: NA | BO8: NA | BP8: 0.7699982 | BQ8: 3.2693248 | BR8: NA | BS8: NA | BT8: NA | BU8: NA | BV8: NA | BW8: 0 | BX8: 160 | BY8: 80 | BZ8: 0 | CA8: 0 | CB8: 0 | CC8: 0 | CD8: 0 | CE8: 0 | CF8: 130 | CG8: 70 | CH8: 0 | CI8: 0 | CJ8: 0 | CK8: 0 | CL8: 0 | CM8: 0 | CN8: 30 | CO8: 10 | CP8: 0 | CQ8: 0 | CR8: 0 | CS8: 0 | CT8: 0 | CU8: 0 | CV8: 601.11557 | CW8: 31.287798 | CX8: 0 | CY8: 0 | CZ8: 0 | DA8: 0 | DB8: 0 | DC8: 0 | DD8: 596.48699 | DE8: 30.264898 | DF8: 0 | DG8: 0 | DH8: 0 | DI8: 0 | DJ8: 0 | DK8: 0 | DL8: 4.6285791 | DM8: 1.0228997 | DN8: 0 | DO8: 0 | DP8: 0 | DQ8: 0 | DR8: 0 | DS8: NA | DT8: 66.66458 | DU8: 21.508923 | DV8: NA | DW8: NA | DX8: NA | DY8: NA | DZ8: NA | EA8: NA | EB8: 73.672425 | EC8: 22.615008 | ED8: NA | EE8: NA | EF8: NA | EG8: NA | EH8: NA | EI8: NA | EJ8: 13.509503 | EK8: 11 | EL8: NA | EM8: NA | EN8: NA | EO8: NA | EP8: NA | EQ8: 80 | ER8: 70 | ES8: 10 | ET8: 31.287798 | EU8: 30.264898 | EV8: 1.0228997 | EW8: 12.5 | EX8: 3.2693248 | EY8: 21.508923 | EZ8: 22.615008 | FA8: 11 | FB8: 0 | FC8: 30.769231 | FD8: 110 | FE8: 130 | FF8: 0 | FG8: 0 | FH8: 0 | FI8: NA | FJ8: NA | FK8: 73.672425 | FL8: 22.615008 | FM8: NA | FN8: NA | FO8: NA | FP8: NA | FQ8: NA | FR8: 16.666667 | FS8: 87.5 | FT8: 0 | FU8: 0
A9: BB19 | B9: Stake | C9: UNBURNED | D9: 111 | E9: Yes | F9: 37.19932606333333 | G9: -122.24362967833333 | H9: 2 | I9: 2025-06-30 15:50 | J9: No | K9: SESE | L9: 0 | M9: 0 | N9: 0 | O9: 0.0099999998 | P9: 170.41 | Q9: 103.54121 | R9: 0.074074074 | S9: 0.92592593 | T9: 0.87407407 | U9: 0.051851852 | V9: 0 | W9: 0 | X9: 0.051851852 | Y9: 0.44444444 | Z9: 0 | AA9: 0.42962963 | AB9: 0.074074074 | AC9: 0.92592593 | AD9: 0.87407407 | AE9: 0.051851852 | AF9: 0 | AG9: NA | AH9: 12.798673 | AI9: 87.201327 | AJ9: 0.22911956 | AK9: 0.48854403 | AL9: 1.246704 | AM9: 3.7206996 | AN9: 5.4559476 | AO9: 209.19821 | AP9: 0 | AQ9: 209.19821 | AR9: 209.19821 | AS9: 214.65416 | AT9: 0.875 | AU9: 2.125 | AV9: 60 | AW9: 50 | AX9: 10 | AY9: 16.666667 | AZ9: 190.69869 | BA9: 187.6469 | BB9: 3.0517918 | BC9: 1.6003213 | BD9: 61.31608 | BE9: 66.628778 | BF9: 19 | BG9: NA | BH9: 25 | BI9: 0 | BJ9: NA | BK9: NA | BL9: NA | BM9: NA | BN9: NA | BO9: NA | BP9: 2.2810147 | BQ9: 0 | BR9: NA | BS9: NA | BT9: NA | BU9: NA | BV9: NA | BW9: 0 | BX9: 40 | BY9: 20 | BZ9: 0 | CA9: 0 | CB9: 0 | CC9: 0 | CD9: 0 | CE9: 0 | CF9: 30 | CG9: 20 | CH9: 0 | CI9: 0 | CJ9: 0 | CK9: 0 | CL9: 0 | CM9: 0 | CN9: 10 | CO9: 0 | CP9: 0 | CQ9: 0 | CR9: 0 | CS9: 0 | CT9: 0 | CU9: 0 | CV9: 133.79098 | CW9: 56.907717 | CX9: 0 | CY9: 0 | CZ9: 0 | DA9: 0 | DB9: 0 | DC9: 0 | DD9: 130.73918 | DE9: 56.907717 | DF9: 0 | DG9: 0 | DH9: 0 | DI9: 0 | DJ9: 0 | DK9: 0 | DL9: 3.0517918 | DM9: 0 | DN9: 0 | DO9: 0 | DP9: 0 | DQ9: 0 | DR9: 0 | DS9: NA | DT9: 62.901292 | DU9: 58.01586 | DV9: NA | DW9: NA | DX9: NA | DY9: NA | DZ9: NA | EA9: NA | EB9: 71.799002 | EC9: 58.01586 | ED9: NA | EE9: NA | EF9: NA | EG9: NA | EH9: NA | EI9: NA | EJ9: 19 | EK9: NA | EL9: NA | EM9: NA | EN9: NA | EO9: NA | EP9: NA | EQ9: 20 | ER9: 20 | ES9: 0 | ET9: 56.907717 | EU9: 56.907717 | EV9: 0 | EW9: 0 | EX9: 0 | EY9: 58.01586 | EZ9: 58.01586 | FA9: NA | FB9: 0 | FC9: 100 | FD9: 50 | FE9: 10 | FF9: 200 | FG9: 0 | FH9: 200 | FI9: 100 | FJ9: NA | FK9: 71.799002 | FL9: 58.01586 | FM9: NA | FN9: NA | FO9: NA | FP9: NA | FQ9: NA | FR9: 0 | FS9: 100 | FT9: 0 | FU9: 0
A10: BB20 | B10: Rebar | C10: UNBURNED | D10: 96 | E10: Yes | F10: 37.198767303333334 | G10: -122.25585183749999 | H10: 2 | I10: 2025-07-01 9:18 | J10: No | K10: SESE | L10: 0 | M10: 0 | N10: 0 | O10: 0 | P10: 130.92 | Q10: 70.15813 | R10: 0.038647343 | S10: 0.96135266 | T10: 0.92753623 | U10: 0.033816425 | V10: 0 | W10: 0.52173913 | X10: 0.033816425 | Y10: 0.4057971 | Z10: 0 | AA10: 0 | AB10: 0.038647343 | AC10: 0.96135266 | AD10: 0.92753623 | AE10: 0.033816425 | AF10: =_xlfn.XLOOKUP(A10, ceanothus_cover!$A:$A, ceanothus_cover!$D:$D, "") -> 0.88495575 | AG10: =_xlfn.XLOOKUP(A10, ceanothus_cover!$A:$A, ceanothus_cover!$E:$E, "") -> 0.35 | AH10: 31.261062 | AI10: 68.738938 | AJ10: 1.1349305 | AK10: 0.68396165 | AL10: 2.181732 | AM10: 1.2402332 | AN10: 4.1059268 | AO10: 14.069823 | AP10: 2.765527 | AQ10: 16.83535 | AR10: 16.83535 | AS10: 20.941277 | AT10: 1.125 | AU10: 0.875 | AV10: 170 | AW10: 140 | AX10: 30 | AY10: 17.647059 | AZ10: 107.22466 | BA10: 101.93382 | BB10: 5.2908433 | BC10: 4.9343529 | BD10: 27.314863 | BE10: 29.347511 | BF10: 14.443684 | BG10: 33.333333 | BH10: 0 | BI10: 20 | BJ10: NA | BK10: NA | BL10: NA | BM10: NA | BN10: NA | BO10: 5.9590144 | BP10: 0 | BQ10: 10.714877 | BR10: NA | BS10: NA | BT10: NA | BU10: NA | BV10: NA | BW10: 30 | BX10: 40 | BY10: 100 | BZ10: 0 | CA10: 0 | CB10: 0 | CC10: 0 | CD10: 0 | CE10: 20 | CF10: 40 | CG10: 80 | CH10: 0 | CI10: 0 | CJ10: 0 | CK10: 0 | CL10: 0 | CM10: 10 | CN10: 0 | CO10: 20 | CP10: 0 | CQ10: 0 | CR10: 0 | CS10: 0 | CT10: 0 | CU10: 28.204051 | CV10: 45.327647 | CW10: 33.692965 | CX10: 0 | CY10: 0 | CZ10: 0 | DA10: 0 | DB10: 0 | DC10: 26.523368 | DD10: 45.327647 | DE10: 30.082805 | DF10: 0 | DG10: 0 | DH10: 0 | DI10: 0 | DJ10: 0 | DK10: 1.6806835 | DL10: 0 | DM10: 3.6101598 | DN10: 0 | DO10: 0 | DP10: 0 | DQ10: 0 | DR10: 0 | DS10: 33.348113 | DT10: 36.612361 | DU10: 19.963917 | DV10: NA | DW10: NA | DX10: NA | DY10: NA | DZ10: NA | EA10: 39.607323 | EB10: 36.612361 | EC10: 21.090667 | ED10: NA | EE10: NA | EF10: NA | EG10: NA | EH10: NA | EI10: 14.1 | EJ10: NA | EK10: 14.612495 | EL10: NA | EM10: NA | EN10: NA | EO10: NA | EP10: NA | EQ10: 100 | ER10: 80 | ES10: 20 | ET10: 33.692965 | EU10: 30.082805 | EV10: 3.6101598 | EW10: 20 | EX10: 10.714877 | EY10: 19.963917 | EZ10: 21.090667 | FA10: 14.612495 | FB10: 0 | FC10: 23.076923 | FD10: 40 | FE10: 130 | FF10: 0 | FG10: 0 | FH10: 0 | FI10: NA | FJ10: 39.607323 | FK10: 36.612361 | FL10: 21.090667 | FM10: NA | FN10: NA | FO10: NA | FP10: NA | FQ10: NA | FR10: 5.8823529 | FS10: 94.117647 | FT10: 0 | FU10: 0
A11: BB21 | B11: Rebar | C11: UNBURNED | D11: 180 | E11: Yes | F11: 37.19647239700001 | G11: -122.25850220766667 | H11: 1 | I11: 2025-07-16 | J11: No | K11: SESE | L11: 0 | M11: 0 | N11: 0 | O11: 0 | P11: 141.81 | Q11: 79.864403 | R11: 0.048543689 | S11: 0.95145631 | T11: 0.95145631 | U11: 0 | V11: 0 | W11: 0 | X11: 0 | Y11: 0.11650485 | Z11: 0 | AA11: 0.83495146 | AB11: 0.048543689 | AC11: 0.95145631 | AD11: 0.95145631 | AE11: 0 | AF11: =_xlfn.XLOOKUP(A11, ceanothus_cover!$A:$A, ceanothus_cover!$D:$D, "") -> 9.7345133 | AG11: =_xlfn.XLOOKUP(A11, ceanothus_cover!$A:$A, ceanothus_cover!$E:$E, "") -> 1.7315523 | AH11: 17.433628 | AI11: 82.566372 | AJ11: 1.8621249 | AK11: 0.86309446 | AL11: 3.1167599 | AM11: 0 | AN11: 3.9798544 | AO11: 2.7369445 | AP11: 0 | AQ11: 2.7369445 | AR11: 2.7369445 | AS11: 6.7167989 | AT11: 1.75 | AU11: 1.25 | AV11: 170 | AW11: 110 | AX11: 60 | AY11: 35.294118 | AZ11: 302.29325 | BA11: 291.68164 | BB11: 10.611613 | BC11: 3.5103704 | BD11: 45.863365 | BE11: 56.005974 | BF11: 14.464093 | BG11: NA | BH11: 31.25 | BI11: 100 | BJ11: NA | BK11: NA | BL11: NA | BM11: NA | BN11: NA | BO11: NA | BP11: 3.2397776 | BQ11: 100 | BR11: NA | BS11: NA | BT11: NA | BU11: NA | BV11: NA | BW11: 0 | BX11: 160 | BY11: 10 | BZ11: 0 | CA11: 0 | CB11: 0 | CC11: 0 | CD11: 0 | CE11: 0 | CF11: 110 | CG11: 0 | CH11: 0 | CI11: 0 | CJ11: 0 | CK11: 0 | CL11: 0 | CM11: 0 | CN11: 50 | CO11: 10 | CP11: 0 | CQ11: 0 | CR11: 0 | CS11: 0 | CT11: 0 | CU11: 0 | CV11: 301.44788 | CW11: 0.84537169 | CX11: 0 | CY11: 0 | CZ11: 0 | DA11: 0 | DB11: 0 | DC11: 0 | DD11: 291.68164 | DE11: 0 | DF11: 0 | DG11: 0 | DH11: 0 | DI11: 0 | DJ11: 0 | DK11: 0 | DL11: 9.766241 | DM11: 0.84537169 | DN11: 0 | DO11: 0 | DP11: 0 | DQ11: 0 | DR11: 0 | DS11: NA | DT11: 47.208725 | DU11: 10 | DV11: NA | DW11: NA | DX11: NA | DY11: NA | DZ11: NA | EA11: NA | EB11: 56.005974 | EC11: NA | ED11: NA | EE11: NA | EF11: NA | EG11: NA | EH11: NA | EI11: NA | EJ11: 15.200395 | EK11: 10 | EL11: NA | EM11: NA | EN11: NA | EO11: NA | EP11: NA | EQ11: 10 | ER11: 0 | ES11: 10 | ET11: 0.84537169 | EU11: 0 | EV11: 0.84537169 | EW11: 100 | EX11: 100 | EY11: 10 | EZ11: NA | FA11: 10 | FB11: 0 | FC11: 60 | FD11: 70 | FE11: 100 | FF11: 300 | FG11: 300 | FH11: 0 | FI11: 0 | FJ11: NA | FK11: 56.005974 | FL11: NA | FM11: NA | FN11: NA | FO11: NA | FP11: NA | FQ11: NA | FR11: 58.823529 | FS11: 100 | FT11: 0 | FU11: 0
A12: BB22 | B12: Stake | C12: UNBURNED | D12: 92 | E12: No | F12: 37.197801104999996 | G12: -122.25027157499999 | H12: 1 | I12: 2025-07-02 16:15 | J12: No | K12: SESE | L12: 0 | M12: 0 | N12: 0 | O12: 0 | P12: 160.23 | Q12: 102.9746 | R12: 0.17829457 | S12: 0.82170543 | T12: 0.82170543 | U12: 0 | V12: 0 | W12: 0 | X12: 0 | Y12: 0.60465116 | Z12: 0 | AA12: 0.21705426 | AB12: 0.17829457 | AC12: 0.82170543 | AD12: 0.82170543 | AE12: 0 | AF12: 0 | AG12: NA | AH12: 16.59292 | AI12: 83.40708 | AJ12: 1.083536 | AK12: 0.79795525 | AL12: 3.1167599 | AM12: 0 | AN12: 3.9147152 | AO12: 38.564429 | AP12: 26.182505 | AQ12: 64.746934 | AR12: 64.746934 | AS12: 68.661649 | AT12: 2.125 | AU12: 2.125 | AV12: 100 | AW12: 90 | AX12: 10 | AY12: 10 | AZ12: 315.88826 | BA12: 303.03016 | BB12: 12.858103 | BC12: 4.0704594 | BD12: 61.128381 | BE12: 63.109948 | BF12: 39 | BG12: NA | BH12: 16.666667 | BI12: 0 | BJ12: NA | BK12: NA | BL12: NA | BM12: NA | BN12: NA | BO12: NA | BP12: 6.7947954 | BQ12: 0 | BR12: NA | BS12: NA | BT12: NA | BU12: NA | BV12: NA | BW12: 0 | BX12: 60 | BY12: 40 | BZ12: 0 | CA12: 0 | CB12: 0 | CC12: 0 | CD12: 0 | CE12: 0 | CF12: 50 | CG12: 40 | CH12: 0 | CI12: 0 | CJ12: 0 | CK12: 0 | CL12: 0 | CM12: 0 | CN12: 10 | CO12: 0 | CP12: 0 | CQ12: 0 | CR12: 0 | CS12: 0 | CT12: 0 | CU12: 0 | CV12: 189.23459 | CW12: 126.65367 | CX12: 0 | CY12: 0 | CZ12: 0 | DA12: 0 | DB12: 0 | DC12: 0 | DD12: 176.37649 | DE12: 126.65367 | DF12: 0 | DG12: 0 | DH12: 0 | DI12: 0 | DJ12: 0 | DK12: 0 | DL12: 12.858103 | DM12: 0 | DN12: 0 | DO12: 0 | DP12: 0 | DQ12: 0 | DR12: 0 | DS12: NA | DT12: 61.080248 | DU12: 61.200511 | DV12: NA | DW12: NA | DX12: NA | DY12: NA | DZ12: NA | EA12: NA | EB12: 64.596873 | EC12: 61.200511 | ED12: NA | EE12: NA | EF12: NA | EG12: NA | EH12: NA | EI12: NA | EJ12: 39 | EK12: NA | EL12: NA | EM12: NA | EN12: NA | EO12: NA | EP12: NA | EQ12: 40 | ER12: 40 | ES12: 0 | ET12: 126.65367 | EU12: 126.65367 | EV12: 0 | EW12: 0 | EX12: 0 | EY12: 61.200511 | EZ12: 61.200511 | FA12: NA | FB12: 11.111111 | FC12: 0 | FD12: 90 | FE12: 10 | FF12: 0 | FG12: 0 | FH12: 0 | FI12: NA | FJ12: NA | FK12: 64.596873 | FL12: 61.200511 | FM12: NA | FN12: NA | FO12: NA | FP12: NA | FQ12: NA | FR12: 10 | FS12: 100 | FT12: 0 | FU12: 0
A13: BB23 | B13: Rebar | C13: UNBURNED | D13: 108 | E13: Yes | F13: 37.19763300470956 | G13: -122.24350928950734 | H13: 1 | I13: 2025-06-30 12:00 | J13: No | K13: SESE | L13: 0 | M13: 0 | N13: 0 | O13: 14.25 | P13: 157.53999 | Q13: 89.98203 | R13: 0.0086206897 | S13: 0.99137931 | T13: 0.93103448 | U13: 0.060344828 | V13: 0 | W13: 0 | X13: 0.060344828 | Y13: 0.80172414 | Z13: 0 | AA13: 0.12931034 | AB13: 0.0086206897 | AC13: 0.99137931 | AD13: 0.93103448 | AE13: 0.060344828 | AF13: 0 | AG13: NA | AH13: 7.920354 | AI13: 92.079646 | AJ13: 0.53167567 | AK13: 0.81424006 | AL13: 1.870056 | AM13: 4.9609328 | AN13: 7.6452288 | AO13: 39.819226 | AP13: 0 | AQ13: 39.819226 | AR13: 39.819226 | AS13: 47.464454 | AT13: 0.8125 | AU13: 1.0625 | AV13: 150 | AW13: 130 | AX13: 20 | AY13: 13.333333 | AZ13: 73.150942 | BA13: 65.080601 | BB13: 8.0703408 | BC13: 11.03245 | BD13: 24.018201 | BE13: 24.334938 | BF13: 21.847769 | BG13: NA | BH13: 0 | BI13: 28.571429 | BJ13: NA | BK13: NA | BL13: NA | BM13: NA | BN13: NA | BO13: NA | BP13: 0 | BQ13: 23.652432 | BR13: NA | BS13: NA | BT13: NA | BU13: NA | BV13: NA | BW13: 0 | BX13: 80 | BY13: 70 | BZ13: 0 | CA13: 0 | CB13: 0 | CC13: 0 | CD13: 0 | CE13: 0 | CF13: 80 | CG13: 50 | CH13: 0 | CI13: 0 | CJ13: 0 | CK13: 0 | CL13: 0 | CM13: 0 | CN13: 0 | CO13: 20 | CP13: 0 | CQ13: 0 | CR13: 0 | CS13: 0 | CT13: 0 | CU13: 0 | CV13: 39.030388 | CW13: 34.120554 | CX13: 0 | CY13: 0 | CZ13: 0 | DA13: 0 | DB13: 0 | DC13: 0 | DD13: 39.030388 | DE13: 26.050213 | DF13: 0 | DG13: 0 | DH13: 0 | DI13: 0 | DJ13: 0 | DK13: 0 | DL13: 0 | DM13: 8.0703408 | DN13: 0 | DO13: 0 | DP13: 0 | DQ13: 0 | DR13: 0 | DS13: NA | DT13: 24.023296 | DU13: 24.012378 | DV13: NA | DW13: NA | DX13: NA | DY13: NA | DZ13: NA | EA13: NA | EB13: 24.023296 | EC13: 24.825431 | ED13: NA | EE13: NA | EF13: NA | EG13: NA | EH13: NA | EI13: NA | EJ13: NA | EK13: 21.847769 | EL13: NA | EM13: NA | EN13: NA | EO13: NA | EP13: NA | EQ13: 70 | ER13: 50 | ES13: 20 | ET13: 34.120554 | EU13: 26.050213 | EV13: 8.0703408 | EW13: 28.571429 | EX13: 23.652432 | EY13: 24.012378 | EZ13: 24.825431 | FA13: 21.847769 | FB13: 0 | FC13: 16.666667 | FD13: 30 | FE13: 120 | FF13: 0 | FG13: 0 | FH13: 0 | FI13: NA | FJ13: NA | FK13: 24.023296 | FL13: 24.825431 | FM13: NA | FN13: NA | FO13: NA | FP13: NA | FQ13: NA | FR13: 20 | FS13: 80 | FT13: 0 | FU13: 0
A14: BB24 | B14: Rebar | C14: UNBURNED | D14: 330 | E14: Yes | F14: 37.19304841833333 | G14: -122.24526802666666 | H14: 2 | I14: 2025-07-15 09:28 | J14: No | K14: SESE | L14: 0 | M14: 0 | N14: 0 | O14: 0.15000001 | P14: 136.35001 | Q14: 55.184872 | R14: 0.13333333 | S14: 0.86666667 | T14: 0.8 | U14: 0.066666667 | V14: 0 | W14: 0 | X14: 0 | Y14: 0 | Z14: 0.066666667 | AA14: 0.8 | AB14: 0.13333333 | AC14: 0.86666667 | AD14: 0.8 | AE14: 0.066666667 | AF14: =_xlfn.XLOOKUP(A14, ceanothus_cover!$A:$A, ceanothus_cover!$D:$D, "") -> 16.526549 | AG14: =_xlfn.XLOOKUP(A14, ceanothus_cover!$A:$A, ceanothus_cover!$E:$E, "") -> 1.5955357 | AH14: 16.526549 | AI14: 83.473451 | AJ14: 1.5955357 | AK14: 0.47225923 | AL14: 0.31167599 | AM14: 0 | AN14: 0.78393523 | AO14: 0 | AP14: 0 | AQ14: 0 | AR14: 0 | AS14: 0.78393523 | AT14: 2.375 | AU14: 1.5 | AV14: 170 | AW14: 150 | AX14: 20 | AY14: 11.764706 | AZ14: 263.01906 | BA14: 227.67407 | BB14: 35.34499 | BC14: 13.438186 | BD14: 42.780445 | BE14: 42.372814 | BF14: 45.721986 | BG14: 0 | BH14: 12.5 | BI14: NA | BJ14: NA | BK14: NA | BL14: NA | BM14: NA | BN14: NA | BO14: 0 | BP14: 13.589293 | BQ14: NA | BR14: NA | BS14: NA | BT14: NA | BU14: NA | BV14: NA | BW14: 10 | BX14: 160 | BY14: 0 | BZ14: 0 | CA14: 0 | CB14: 0 | CC14: 0 | CD14: 0 | CE14: 10 | CF14: 140 | CG14: 0 | CH14: 0 | CI14: 0 | CJ14: 0 | CK14: 0 | CL14: 0 | CM14: 0 | CN14: 20 | CO14: 0 | CP14: 0 | CQ14: 0 | CR14: 0 | CS14: 0 | CT14: 0 | CU14: 2.9246479 | CV14: 260.09441 | CW14: 0 | CX14: 0 | CY14: 0 | CZ14: 0 | DA14: 0 | DB14: 0 | DC14: 2.9246479 | DD14: 224.74942 | DE14: 0 | DF14: 0 | DG14: 0 | DH14: 0 | DI14: 0 | DJ14: 0 | DK14: 0 | DL14: 35.34499 | DM14: 0 | DN14: 0 | DO14: 0 | DP14: 0 | DQ14: 0 | DR14: 0 | DS14: 18.6 | DT14: 43.851219 | DU14: NA | DV14: NA | DW14: NA | DX14: NA | DY14: NA | DZ14: NA | EA14: 18.6 | EB14: 43.577411 | EC14: NA | ED14: NA | EE14: NA | EF14: NA | EG14: NA | EH14: NA | EI14: NA | EJ14: 45.721986 | EK14: NA | EL14: NA | EM14: NA | EN14: NA | EO14: NA | EP14: NA | EQ14: 0 | ER14: 0 | ES14: 0 | ET14: 0 | EU14: 0 | EV14: 0 | EW14: NA | EX14: NA | EY14: NA | EZ14: NA | FA14: NA | FB14: 14.285714 | FC14: 10 | FD14: 70 | FE14: 100 | FF14: 300 | FG14: 300 | FH14: 0 | FI14: 0 | FJ14: 18.6 | FK14: 43.577411 | FL14: NA | FM14: NA | FN14: NA | FO14: NA | FP14: NA | FQ14: NA | FR14: 47.058824 | FS14: 94.117647 | FT14: 0 | FU14: 0
A15: BB25 | B15: Rebar | C15: UNBURNED | D15: 530 | E15: Yes | F15: 37.20387077516666 | G15: -122.25198882049999 | H15: 1 | I15: 2025-07-03 13:32 | J15: No | K15: SESE | L15: 0 | M15: 0 | N15: 0 | O15: 0 | P15: 87.529999 | Q15: 53.73285 | R15: 0.89090909 | S15: 0.10909091 | T15: 0.10909091 | U15: 0 | V15: 0 | W15: 0 | X15: 0 | Y15: 0.10909091 | Z15: 0 | AA15: 0 | AB15: 0.89090909 | AC15: 0.10909091 | AD15: 0.10909091 | AE15: 0 | AF15: =_xlfn.XLOOKUP(A15, ceanothus_cover!$A:$A, ceanothus_cover!$D:$D, "") -> 92.477876 | AG15: =_xlfn.XLOOKUP(A15, ceanothus_cover!$A:$A, ceanothus_cover!$E:$E, "") -> 2.952381 | AH15: 98.672566 | AI15: 1.3274336 | AJ15: 2.9090909 | AK15: 1.5307713 | AL15: 2.493408 | AM15: 1.2402332 | AN15: 5.2644125 | AO15: 19.658697 | AP15: 0 | AQ15: 19.658697 | AR15: 19.658697 | AS15: 24.92311 | AT15: 5.875 | AU15: 0.75 | AV15: 90 | AW15: 0 | AX15: 90 | AY15: 100 | AZ15: 83.585619 | BA15: 0 | BB15: 83.585619 | BC15: 100 | BD15: 33.145202 | BE15: NA | BF15: 33.145202 | BG15: NA | BH15: 100 | BI15: 100 | BJ15: 100 | BK15: NA | BL15: NA | BM15: NA | BN15: NA | BO15: NA | BP15: 100 | BQ15: 100 | BR15: 100 | BS15: NA | BT15: NA | BU15: NA | BV15: NA | BW15: 0 | BX15: 20 | BY15: 60 | BZ15: 10 | CA15: 0 | CB15: 0 | CC15: 0 | CD15: 0 | CE15: 0 | CF15: 0 | CG15: 0 | CH15: 0 | CI15: 0 | CJ15: 0 | CK15: 0 | CL15: 0 | CM15: 0 | CN15: 20 | CO15: 60 | CP15: 10 | CQ15: 0 | CR15: 0 | CS15: 0 | CT15: 0 | CU15: 0 | CV15: 25.353881 | CW15: 44.296969 | CX15: 13.934769 | CY15: 0 | CZ15: 0 | DA15: 0 | DB15: 0 | DC15: 0 | DD15: 0 | DE15: 0 | DF15: 0 | DG15: 0 | DH15: 0 | DI15: 0 | DJ15: 0 | DK15: 0 | DL15: 25.353881 | DM15: 44.296969 | DN15: 13.934769 | DO15: 0 | DP15: 0 | DQ15: 0 | DR15: 0 | DS15: NA | DT15: 38.724282 | DU15: 29.552044 | DV15: 40.6 | DW15: NA | DX15: NA | DY15: NA | DZ15: NA | EA15: NA | EB15: NA | EC15: NA | ED15: NA | EE15: NA | EF15: NA | EG15: NA | EH15: NA | EI15: NA | EJ15: 38.724282 | EK15: 29.552044 | EL15: 40.6 | EM15: NA | EN15: NA | EO15: NA | EP15: NA | EQ15: 70 | ER15: 0 | ES15: 70 | ET15: 58.231738 | EU15: 0 | EV15: 58.231738 | EW15: 100 | EX15: 100 | EY15: 31.369457 | EZ15: NA | FA15: 31.369457 | FB15: 100 | FC15: 100 | FD15: 50 | FE15: 40 | FF15: 0 | FG15: 0 | FH15: 0 | FI15: NA | FJ15: NA | FK15: NA | FL15: NA | FM15: NA | FN15: NA | FO15: NA | FP15: NA | FQ15: NA | FR15: 11.111111 | FS15: 11.111111 | FT15: 0 | FU15: 0
A16: BB26 | B16: Rebar | C16: UNBURNED | D16: 438 | E16: Yes | F16: 37.19581897 | G16: -122.25043165333334 | H16: 1 | I16: 2025-07-02 10:55 | J16: No | K16: SESE | L16: 61 | M16: 2 | N16: 0 | O16: 0 | P16: 123.11 | Q16: 68.281679 | R16: 0.42391304 | S16: 0.57608696 | T16: 0.34782609 | U16: 0.22826087 | V16: 0 | W16: 0 | X16: 0.22826087 | Y16: 0.26086957 | Z16: 0 | AA16: 0.086956522 | AB16: 0.42391304 | AC16: 0.57608696 | AD16: 0.34782609 | AE16: 0.22826087 | AF16: =_xlfn.XLOOKUP(A16, ceanothus_cover!$A:$A, ceanothus_cover!$D:$D, "") -> 33.849558 | AG16: =_xlfn.XLOOKUP(A16, ceanothus_cover!$A:$A, ceanothus_cover!$E:$E, "") -> 4.0423729 | AH16: 54.756637 | AI16: 45.243363 | AJ16: 3.3610909 | AK16: 0.52111364 | AL16: 2.181732 | AM16: 6.201166 | AN16: 8.9040116 | AO16: 64.168955 | AP16: 0 | AQ16: 64.168955 | AR16: 64.168955 | AS16: 73.072966 | AT16: 2.5 | AU16: 3.75 | AV16: 70 | AW16: 0 | AX16: 70 | AY16: 100 | AZ16: 146.39344 | BA16: 0 | BB16: 146.39344 | BC16: 100 | BD16: 49.737956 | BE16: NA | BF16: 49.737956 | BG16: NA | BH16: NA | BI16: 100 | BJ16: NA | BK16: NA | BL16: NA | BM16: NA | BN16: NA | BO16: NA | BP16: NA | BQ16: 100 | BR16: NA | BS16: NA | BT16: NA | BU16: NA | BV16: NA | BW16: 0 | BX16: 0 | BY16: 70 | BZ16: 0 | CA16: 0 | CB16: 0 | CC16: 0 | CD16: 0 | CE16: 0 | CF16: 0 | CG16: 0 | CH16: 0 | CI16: 0 | CJ16: 0 | CK16: 0 | CL16: 0 | CM16: 0 | CN16: 0 | CO16: 70 | CP16: 0 | CQ16: 0 | CR16: 0 | CS16: 0 | CT16: 0 | CU16: 0 | CV16: 0 | CW16: 146.39344 | CX16: 0 | CY16: 0 | CZ16: 0 | DA16: 0 | DB16: 0 | DC16: 0 | DD16: 0 | DE16: 0 | DF16: 0 | DG16: 0 | DH16: 0 | DI16: 0 | DJ16: 0 | DK16: 0 | DL16: 0 | DM16: 146.39344 | DN16: 0 | DO16: 0 | DP16: 0 | DQ16: 0 | DR16: 0 | DS16: NA | DT16: NA | DU16: 49.737956 | DV16: NA | DW16: NA | DX16: NA | DY16: NA | DZ16: NA | EA16: NA | EB16: NA | EC16: NA | ED16: NA | EE16: NA | EF16: NA | EG16: NA | EH16: NA | EI16: NA | EJ16: NA | EK16: 49.737956 | EL16: NA | EM16: NA | EN16: NA | EO16: NA | EP16: NA | EQ16: 70 | ER16: 0 | ES16: 70 | ET16: 146.39344 | EU16: 0 | EV16: 146.39344 | EW16: 100 | EX16: 100 | EY16: 49.737956 | EZ16: NA | FA16: 49.737956 | FB16: 100 | FC16: 100 | FD16: 60 | FE16: 10 | FF16: 400 | FG16: 400 | FH16: 0 | FI16: 0 | FJ16: NA | FK16: NA | FL16: NA | FM16: NA | FN16: NA | FO16: NA | FP16: NA | FQ16: NA | FR16: 0 | FS16: 85.714286 | FT16: 0 | FU16: 0
A17: BB27 | B17: Rebar | C17: UNBURNED | D17: 260 | E17: Yes | F17: 37.20613923833333 | G17: -122.24435374833335 | H17: 2 | I17: 2025-07-03 10:48 | J17: No | K17: SESE | L17: 0 | M17: 0 | N17: 0 | O17: 33.77 | P17: 117.57 | Q17: 90.577244 | R17: 0.15151515 | S17: 0.84848485 | T17: 0.70707071 | U17: 0.14141414 | V17: 0 | W17: 0.080808081 | X17: 0.14141414 | Y17: 0 | Z17: 0 | AA17: 0.62626263 | AB17: 0.15151515 | AC17: 0.84848485 | AD17: 0.70707071 | AE17: 0.14141414 | AF17: =_xlfn.XLOOKUP(A17, ceanothus_cover!$A:$A, ceanothus_cover!$D:$D, "") -> 50.221239 | AG17: =_xlfn.XLOOKUP(A17, ceanothus_cover!$A:$A, ceanothus_cover!$E:$E, "") -> 3 | AH17: 50.995575 | AI17: 49.004425 | AJ17: 2.9633891 | AK17: 0.87937926 | AL17: 8.1035759 | AM17: 11.162099 | AN17: 20.145054 | AO17: 7.8765701 | AP17: 0 | AQ17: 7.8765701 | AR17: 7.8765701 | AS17: 28.021624 | AT17: 2.375 | AU17: 2.25 | AV17: 190 | AW17: 150 | AX17: 40 | AY17: 21.052632 | AZ17: 540.37452 | BA17: 489.79103 | BB17: 50.583491 | BC17: 9.360821 | BD17: 58.002509 | BE17: 62.149256 | BF17: 38.676802 | BG17: 0 | BH17: 21.428571 | BI17: 50 | BJ17: NA | BK17: NA | BL17: NA | BM17: NA | BN17: NA | BO17: 0 | BP17: 4.5586178 | BQ17: 50.48153 | BR17: NA | BS17: NA | BT17: NA | BU17: NA | BV17: NA | BW17: 30 | BX17: 140 | BY17: 20 | BZ17: 0 | CA17: 0 | CB17: 0 | CC17: 0 | CD17: 0 | CE17: 30 | CF17: 110 | CG17: 10 | CH17: 0 | CI17: 0 | CJ17: 0 | CK17: 0 | CL17: 0 | CM17: 0 | CN17: 30 | CO17: 10 | CP17: 0 | CQ17: 0 | CR17: 0 | CS17: 0 | CT17: 0 | CU17: 91.840335 | CV17: 382.91001 | CW17: 65.624175 | CX17: 0 | CY17: 0 | CZ17: 0 | DA17: 0 | DB17: 0 | DC17: 91.840335 | DD17: 365.4546 | DE17: 32.496088 | DF17: 0 | DG17: 0 | DH17: 0 | DI17: 0 | DJ17: 0 | DK17: 0 | DL17: 17.455404 | DM17: 33.128088 | DN17: 0 | DO17: 0 | DP17: 0 | DQ17: 0 | DR17: 0 | DS17: 60.177238 | DT17: 56.880118 | DU17: 62.300722 | DV17: NA | DW17: NA | DX17: NA | DY17: NA | DZ17: NA | EA17: 60.177238 | EB17: 62.689748 | EC17: 62 | ED17: NA | EE17: NA | EF17: NA | EG17: NA | EH17: NA | EI17: NA | EJ17: 26.234964 | EK17: 62.6 | EL17: NA | EM17: NA | EN17: NA | EO17: NA | EP17: NA | EQ17: 20 | ER17: 10 | ES17: 10 | ET17: 65.624175 | EU17: 32.496088 | EV17: 33.128088 | EW17: 50 | EX17: 50.48153 | EY17: 62.300722 | EZ17: 62 | FA17: 62.6 | FB17: 6.25 | FC17: 100 | FD17: 160 | FE17: 30 | FF17: 100 | FG17: 0 | FH17: 100 | FI17: 100 | FJ17: 60.177238 | FK17: 62.689748 | FL17: 62 | FM17: NA | FN17: NA | FO17: NA | FP17: NA | FQ17: NA | FR17: 10.526316 | FS17: 94.736842 | FT17: 0 | FU17: 0
A18: BB28 | B18: Rebar | C18: UNBURNED | D18: 276 | E18: Yes | F18: 37.19534028566666 | G18: -122.25038911600002 | H18: 2 | I18: 2025-07-02 09:02 | J18: No | K18: SESE | L18: 19 | M18: 0 | N18: 0 | O18: 0 | P18: 135.86 | Q18: 73.14736 | R18: 0.65625 | S18: 0.34375 | T18: 0.25 | U18: 0.09375 | V18: 0 | W18: 0 | X18: 0 | Y18: 0.09375 | Z18: 0.09375 | AA18: 0.15625 | AB18: 0.65625 | AC18: 0.34375 | AD18: 0.25 | AE18: 0.09375 | AF18: =_xlfn.XLOOKUP(A18, ceanothus_cover!$A:$A, ceanothus_cover!$D:$D, "") -> 17.212389 | AG18: =_xlfn.XLOOKUP(A18, ceanothus_cover!$A:$A, ceanothus_cover!$E:$E, "") -> 1.4832121 | AH18: 27.278761 | AI18: 72.721239 | AJ18: 1.4017768 | AK18: 0.71653125 | AL18: 0.62335199 | AM18: 7.4413992 | AN18: 8.7812824 | AO18: 79.420264 | AP18: 0 | AQ18: 79.420264 | AR18: 79.420264 | AS18: 88.201546 | AT18: 4.375 | AU18: 4.3125 | AV18: 150 | AW18: 20 | AX18: 130 | AY18: 86.666667 | AZ18: 307.98429 | BA18: 106.64609 | BB18: 201.3382 | BC18: 65.37288 | BD18: 49.282735 | BE18: 79.420684 | BF18: 42.802345 | BG18: NA | BH18: 50 | BI18: 100 | BJ18: NA | BK18: NA | BL18: NA | BM18: NA | BN18: NA | BO18: NA | BP18: 4.6825014 | BQ18: 100 | BR18: NA | BS18: NA | BT18: NA | BU18: NA | BV18: NA | BW18: 0 | BX18: 40 | BY18: 110 | BZ18: 0 | CA18: 0 | CB18: 0 | CC18: 0 | CD18: 0 | CE18: 0 | CF18: 20 | CG18: 0 | CH18: 0 | CI18: 0 | CJ18: 0 | CK18: 0 | CL18: 0 | CM18: 0 | CN18: 20 | CO18: 110 | CP18: 0 | CQ18: 0 | CR18: 0 | CS18: 0 | CT18: 0 | CU18: 0 | CV18: 111.88511 | CW18: 196.09918 | CX18: 0 | CY18: 0 | CZ18: 0 | DA18: 0 | DB18: 0 | DC18: 0 | DD18: 106.64609 | DE18: 0 | DF18: 0 | DG18: 0 | DH18: 0 | DI18: 0 | DJ18: 0 | DK18: 0 | DL18: 5.239022 | DM18: 196.09918 | DN18: 0 | DO18: 0 | DP18: 0 | DQ18: 0 | DR18: 0 | DS18: NA | DT18: 57.521778 | DU18: 45.921672 | DV18: NA | DW18: NA | DX18: NA | DY18: NA | DZ18: NA | EA18: NA | EB18: 79.420684 | EC18: NA | ED18: NA | EE18: NA | EF18: NA | EG18: NA | EH18: NA | EI18: NA | EJ18: 17.602983 | EK18: 45.921672 | EL18: NA | EM18: NA | EN18: NA | EO18: NA | EP18: NA | EQ18: 110 | ER18: 0 | ES18: 110 | ET18: 196.09918 | EU18: 0 | EV18: 196.09918 | EW18: 100 | EX18: 100 | EY18: 45.921672 | EZ18: NA | FA18: 45.921672 | FB18: 81.818182 | FC18: 100 | FD18: 110 | FE18: 40 | FF18: 0 | FG18: 0 | FH18: 0 | FI18: NA | FJ18: NA | FK18: 79.420684 | FL18: NA | FM18: NA | FN18: NA | FO18: NA | FP18: NA | FQ18: NA | FR18: 13.333333 | FS18: 93.333333 | FT18: 0 | FU18: 0
A19: BB29 | B19: Rebar | C19: UNBURNED | D19: 334 | E19: Yes | F19: 37.201001228333325 | G19: -122.25592759166666 | H19: 2 | I19: 2025-07-16 14:44 | J19: No | K19: SESE | L19: 0 | M19: 3 | N19: 0 | O19: 0.02 | P19: 129.86 | Q19: 71.991128 | R19: 0.32467532 | S19: 0.67532468 | T19: 0.5974026 | U19: 0.077922078 | V19: 0 | W19: 0 | X19: 0 | Y19: 0 | Z19: 0.077922078 | AA19: 0.5974026 | AB19: 0.32467532 | AC19: 0.67532468 | AD19: 0.5974026 | AE19: 0.077922078 | AF19: =_xlfn.XLOOKUP(A19, ceanothus_cover!$A:$A, ceanothus_cover!$D:$D, "") -> 25.995575 | AG19: =_xlfn.XLOOKUP(A19, ceanothus_cover!$A:$A, ceanothus_cover!$E:$E, "") -> 3 | AH19: 56.19469 | AI19: 43.80531 | AJ19: 2.2972441 | AK19: 0.61882244 | AL19: 1.55838 | AM19: 1.2402332 | AN19: 3.4174356 | AO19: 18.524122 | AP19: 0 | AQ19: 18.524122 | AR19: 18.524122 | AS19: 21.941558 | AT19: 3.125 | AU19: 0.8125 | AV19: 160 | AW19: 130 | AX19: 30 | AY19: 18.75 | AZ19: 425.03995 | BA19: 396.13957 | BB19: 28.900384 | BC19: 6.7994511 | BD19: 56.057153 | BE19: 60.038328 | BF19: 33.757271 | BG19: NA | BH19: 7.1428571 | BI19: 100 | BJ19: NA | BK19: NA | BL19: NA | BM19: NA | BN19: NA | BO19: NA | BP19: 4.7798243 | BQ19: 100 | BR19: NA | BS19: NA | BT19: NA | BU19: NA | BV19: NA | BW19: 0 | BX19: 140 | BY19: 20 | BZ19: 0 | CA19: 0 | CB19: 0 | CC19: 0 | CD19: 0 | CE19: 0 | CF19: 130 | CG19: 0 | CH19: 0 | CI19: 0 | CJ19: 0 | CK19: 0 | CL19: 0 | CM19: 0 | CN19: 10 | CO19: 20 | CP19: 0 | CQ19: 0 | CR19: 0 | CS19: 0 | CT19: 0 | CU19: 0 | CV19: 416.02482 | CW19: 9.0151282 | CX19: 0 | CY19: 0 | CZ19: 0 | DA19: 0 | DB19: 0 | DC19: 0 | DD19: 396.13957 | DE19: 0 | DF19: 0 | DG19: 0 | DH19: 0 | DI19: 0 | DJ19: 0 | DK19: 0 | DL19: 19.885256 | DM19: 9.0151282 | DN19: 0 | DO19: 0 | DP19: 0 | DQ19: 0 | DR19: 0 | DS19: NA | DT19: 59.288676 | DU19: 23.091232 | DV19: NA | DW19: NA | DX19: NA | DY19: NA | DZ19: NA | EA19: NA | EB19: 60.038328 | EC19: NA | ED19: NA | EE19: NA | EF19: NA | EG19: NA | EH19: NA | EI19: NA | EJ19: 48.5 | EK19: 23.091232 | EL19: NA | EM19: NA | EN19: NA | EO19: NA | EP19: NA | EQ19: 20 | ER19: 0 | ES19: 20 | ET19: 9.0151282 | EU19: 0 | EV19: 9.0151282 | EW19: 100 | EX19: 100 | EY19: 23.091232 | EZ19: NA | FA19: 23.091232 | FB19: 9.0909091 | FC19: 40 | FD19: 110 | FE19: 50 | FF19: 100 | FG19: 100 | FH19: 0 | FI19: 0 | FJ19: NA | FK19: 60.038328 | FL19: NA | FM19: NA | FN19: NA | FO19: NA | FP19: NA | FQ19: NA | FR19: 68.75 | FS19: 81.25 | FT19: 0 | FU19: 0
A20: BB3 | B20: Rebar | C20: UNBURNED | D20: 697 | E20: Yes | F20: 37.20109218533333 | G20: -122.25650606416666 | H20: 2 | I20: 2025-07-01 13:35 | J20: No | K20: SESE | L20: 0 | M20: 0 | N20: 0 | O20: 0 | P20: 125.68999 | Q20: 41.943653 | R20: 0.73333333 | S20: 0.26666667 | T20: 0.26666667 | U20: 0 | V20: 0 | W20: 0 | X20: 0 | Y20: 0.1 | Z20: 0 | AA20: 0.16666667 | AB20: 0.73333333 | AC20: 0.26666667 | AD20: 0.26666667 | AE20: 0 | AF20: =_xlfn.XLOOKUP(A20, ceanothus_cover!$A:$A, ceanothus_cover!$D:$D, "") -> 92.920354 | AG20: =_xlfn.XLOOKUP(A20, ceanothus_cover!$A:$A, ceanothus_cover!$E:$E, "") -> 3.5 | AH20: 92.920354 | AI20: 7.079646 | AJ20: 3.5 | AK20: 1.3027841 | AL20: 4.6751399 | AM20: 0 | AN20: 5.977924 | AO20: 84.438577 | AP20: 0 | AQ20: 84.438577 | AR20: 84.438577 | AS20: 90.416501 | AT20: 2 | AU20: 1.875 | AV20: 60 | AW20: 30 | AX20: 30 | AY20: 50 | AZ20: 119.0296 | BA20: 99.411484 | BB20: 19.618118 | BC20: 16.481714 | BD20: 48.442664 | BE20: 62.608572 | BF20: 27.812767 | BG20: 100 | BH20: 0 | BI20: 100 | BJ20: NA | BK20: NA | BL20: NA | BM20: NA | BN20: NA | BO20: 100 | BP20: 0 | BQ20: 100 | BR20: NA | BS20: NA | BT20: NA | BU20: NA | BV20: NA | BW20: 20 | BX20: 30 | BY20: 10 | BZ20: 0 | CA20: 0 | CB20: 0 | CC20: 0 | CD20: 0 | CE20: 0 | CF20: 30 | CG20: 0 | CH20: 0 | CI20: 0 | CJ20: 0 | CK20: 0 | CL20: 0 | CM20: 20 | CN20: 0 | CO20: 10 | CP20: 0 | CQ20: 0 | CR20: 0 | CS20: 0 | CT20: 0 | CU20: 16.303923 | CV20: 99.411484 | CW20: 3.3141952 | CX20: 0 | CY20: 0 | CZ20: 0 | DA20: 0 | DB20: 0 | DC20: 0 | DD20: 99.411484 | DE20: 0 | DF20: 0 | DG20: 0 | DH20: 0 | DI20: 0 | DJ20: 0 | DK20: 16.303923 | DL20: 0 | DM20: 3.3141952 | DN20: 0 | DO20: 0 | DP20: 0 | DQ20: 0 | DR20: 0 | DS20: 31.053261 | DT20: 62.608572 | DU20: 19.8 | DV20: NA | DW20: NA | DX20: NA | DY20: NA | DZ20: NA | EA20: NA | EB20: 62.608572 | EC20: NA | ED20: NA | EE20: NA | EF20: NA | EG20: NA | EH20: NA | EI20: 31.053261 | EJ20: NA | EK20: 19.8 | EL20: NA | EM20: NA | EN20: NA | EO20: NA | EP20: NA | EQ20: 10 | ER20: 0 | ES20: 10 | ET20: 3.3141952 | EU20: 0 | EV20: 3.3141952 | EW20: 100 | EX20: 100 | EY20: 19.8 | EZ20: NA | FA20: 19.8 | FB20: 40 | FC20: 100 | FD20: 50 | FE20: 10 | FF20: 900 | FG20: 900 | FH20: 0 | FI20: 0 | FJ20: NA | FK20: 62.608572 | FL20: NA | FM20: NA | FN20: NA | FO20: NA | FP20: NA | FQ20: NA | FR20: 50 | FS20: 100 | FT20: 0 | FU20: 0
A21: BB30 | B21: Rebar | C21: UNBURNED | D21: 121 | E21: Yes | F21: 37.19438074333333 | G21: -122.24449449 | H21: 2 | I21: 2025-07-15 11:25 | J21: No | K21: SESE | L21: 2 | M21: 17 | N21: 0 | O21: 0 | P21: 150.02 | Q21: 96.018085 | R21: 0.08496732 | S21: 0.91503268 | T21: 0.91503268 | U21: 0 | V21: 0 | W21: 0.026143791 | X21: 0 | Y21: 0.62745098 | Z21: 0 | AA21: 0.26143791 | AB21: 0.08496732 | AC21: 0.91503268 | AD21: 0.91503268 | AE21: 0 | AF21: =_xlfn.XLOOKUP(A21, ceanothus_cover!$A:$A, ceanothus_cover!$D:$D, "") -> 13.628319 | AG21: =_xlfn.XLOOKUP(A21, ceanothus_cover!$A:$A, ceanothus_cover!$E:$E, "") -> 1.2326087 | AH21: 13.849558 | AI21: 86.150442 | AJ21: 1.2 | AK21: 0.89566406 | AL21: 2.805084 | AM21: 3.7206996 | AN21: 7.4214476 | AO21: 14.299138 | AP21: 0 | AQ21: 14.299138 | AR21: 14.299138 | AS21: 21.720586 | AT21: 0.625 | AU21: 0.875 | AV21: 210 | AW21: 200 | AX21: 10 | AY21: 4.7619048 | AZ21: 433.04368 | BA21: 426.51031 | BB21: 6.5333706 | BC21: 1.5087094 | BD21: 49.389241 | BE21: 50.225691 | BF21: 27.8 | BG21: 0 | BH21: 0 | BI21: 16.666667 | BJ21: NA | BK21: NA | BL21: NA | BM21: NA | BN21: NA | BO21: 0 | BP21: 0 | BQ21: 7.362744 | BR21: NA | BS21: NA | BT21: NA | BU21: NA | BV21: NA | BW21: 30 | BX21: 120 | BY21: 60 | BZ21: 0 | CA21: 0 | CB21: 0 | CC21: 0 | CD21: 0 | CE21: 30 | CF21: 120 | CG21: 50 | CH21: 0 | CI21: 0 | CJ21: 0 | CK21: 0 | CL21: 0 | CM21: 0 | CN21: 0 | CO21: 10 | CP21: 0 | CQ21: 0 | CR21: 0 | CS21: 0 | CT21: 0 | CU21: 83.314931 | CV21: 260.99321 | CW21: 88.735539 | CX21: 0 | CY21: 0 | CZ21: 0 | DA21: 0 | DB21: 0 | DC21: 83.314931 | DD21: 260.99321 | DE21: 82.202168 | DF21: 0 | DG21: 0 | DH21: 0 | DI21: 0 | DJ21: 0 | DK21: 0 | DL21: 0 | DM21: 6.5333706 | DN21: 0 | DO21: 0 | DP21: 0 | DQ21: 0 | DR21: 0 | DS21: 57.316141 | DT21: 50.722439 | DU21: 41.826288 | DV21: NA | DW21: NA | DX21: NA | DY21: NA | DZ21: NA | EA21: 57.316141 | EB21: 50.722439 | EC21: 44.09941 | ED21: NA | EE21: NA | EF21: NA | EG21: NA | EH21: NA | EI21: NA | EJ21: NA | EK21: 27.8 | EL21: NA | EM21: NA | EN21: NA | EO21: NA | EP21: NA | EQ21: 60 | ER21: 50 | ES21: 10 | ET21: 88.735539 | EU21: 82.202168 | EV21: 6.5333706 | EW21: 16.666667 | EX21: 7.362744 | EY21: 41.826288 | EZ21: 44.09941 | FA21: 27.8 | FB21: 0 | FC21: 20 | FD21: 160 | FE21: 50 | FF21: 0 | FG21: 0 | FH21: 0 | FI21: NA | FJ21: 57.316141 | FK21: 50.722439 | FL21: 44.09941 | FM21: NA | FN21: NA | FO21: NA | FP21: NA | FQ21: NA | FR21: 23.809524 | FS21: 100 | FT21: 0 | FU21: 0
A22: BB31 | B22: Rebar | C22: UNBURNED | D22: 266 | E22: Yes | F22: 37.19465625033334 | G22: -122.24941565466666 | H22: 2 | I22: 2025-07-02 11:30 | J22: No | K22: SESE | L22: 0 | M22: 0 | N22: 0 | O22: 0 | P22: 135.31999 | Q22: 64.590638 | R22: 0.578125 | S22: 0.421875 | T22: 0.375 | U22: 0.046875 | V22: 0 | W22: 0 | X22: 0 | Y22: 0 | Z22: 0.046875 | AA22: 0.375 | AB22: 0.578125 | AC22: 0.421875 | AD22: 0.375 | AE22: 0.046875 | AF22: =_xlfn.XLOOKUP(A22, ceanothus_cover!$A:$A, ceanothus_cover!$D:$D, "") -> 2.4336283 | AG22: =_xlfn.XLOOKUP(A22, ceanothus_cover!$A:$A, ceanothus_cover!$E:$E, "") -> 0.5 | AH22: 6.7920354 | AI22: 93.207965 | AJ22: 0.35964912 | AK22: 0.60253764 | AL22: 3.4284359 | AM22: 1.2402332 | AN22: 5.2712068 | AO22: 10.560277 | AP22: 0 | AQ22: 10.560277 | AR22: 10.560277 | AS22: 15.831484 | AT22: 3.375 | AU22: 1.875 | AV22: 100 | AW22: 60 | AX22: 40 | AY22: 40 | AZ22: 258.61695 | BA22: 204.70329 | BB22: 53.913664 | BC22: 20.846918 | BD22: 55.310126 | BE22: 63.527671 | BF22: 39.929657 | BG22: NA | BH22: 14.285714 | BI22: 100 | BJ22: NA | BK22: NA | BL22: NA | BM22: NA | BN22: NA | BO22: NA | BP22: 1.6733478 | BQ22: 100 | BR22: NA | BS22: NA | BT22: NA | BU22: NA | BV22: NA | BW22: 0 | BX22: 70 | BY22: 30 | BZ22: 0 | CA22: 0 | CB22: 0 | CC22: 0 | CD22: 0 | CE22: 0 | CF22: 60 | CG22: 0 | CH22: 0 | CI22: 0 | CJ22: 0 | CK22: 0 | CL22: 0 | CM22: 0 | CN22: 10 | CO22: 30 | CP22: 0 | CQ22: 0 | CR22: 0 | CS22: 0 | CT22: 0 | CU22: 0 | CV22: 208.18698 | CW22: 50.429972 | CX22: 0 | CY22: 0 | CZ22: 0 | DA22: 0 | DB22: 0 | DC22: 0 | DD22: 204.70329 | DE22: 0 | DF22: 0 | DG22: 0 | DH22: 0 | DI22: 0 | DJ22: 0 | DK22: 0 | DL22: 3.4836922 | DM22: 50.429972 | DN22: 0 | DO22: 0 | DP22: 0 | DQ22: 0 | DR22: 0 | DS22: NA | DT22: 59.313549 | DU22: 44.592301 | DV22: NA | DW22: NA | DX22: NA | DY22: NA | DZ22: NA | EA22: NA | EB22: 63.527671 | EC22: NA | ED22: NA | EE22: NA | EF22: NA | EG22: NA | EH22: NA | EI22: NA | EJ22: 20.3 | EK22: 44.592301 | EL22: NA | EM22: NA | EN22: NA | EO22: NA | EP22: NA | EQ22: 30 | ER22: 0 | ES22: 30 | ET22: 50.429972 | EU22: 0 | EV22: 50.429972 | EW22: 100 | EX22: 100 | EY22: 44.592301 | EZ22: NA | FA22: 44.592301 | FB22: 33.333333 | FC22: 100 | FD22: 90 | FE22: 10 | FF22: 0 | FG22: 0 | FH22: 0 | FI22: NA | FJ22: NA | FK22: 63.527671 | FL22: NA | FM22: NA | FN22: NA | FO22: NA | FP22: NA | FQ22: NA | FR22: 10 | FS22: 100 | FT22: 0 | FU22: 0
A23: BB32 | B23: Stake | C23: UNBURNED | D23: 431 | E23: Yes | F23: 37.19399511333333 | G23: -122.26171554333331 | H23: 1 | I23: 2025-07-14 15:38 | J23: No | K23: SESE | L23: 0 | M23: 0 | N23: 0 | O23: 1.16 | P23: 134.34999 | Q23: 85.422286 | R23: 0.045801527 | S23: 0.95419847 | T23: 0.90076336 | U23: 0.053435115 | V23: 0 | W23: 0.18320611 | X23: 0.053435115 | Y23: 0.22900763 | Z23: 0 | AA23: 0.48854962 | AB23: 0.045801527 | AC23: 0.95419847 | AD23: 0.90076336 | AE23: 0.053435115 | AF23: =_xlfn.XLOOKUP(A23, ceanothus_cover!$A:$A, ceanothus_cover!$D:$D, "") -> 36.150442 | AG23: =_xlfn.XLOOKUP(A23, ceanothus_cover!$A:$A, ceanothus_cover!$E:$E, "") -> 1.4524766 | AH23: 55.353982 | AI23: 44.646018 | AJ23: 1.3826176 | AK23: 0.73281605 | AL23: 14.337096 | AM23: 7.4413992 | AN23: 22.511311 | AO23: 18.327753 | AP23: 0 | AQ23: 18.327753 | AR23: 18.327753 | AS23: 40.839064 | AT23: 1.5 | AU23: 3.875 | AV23: 180 | AW23: 140 | AX23: 40 | AY23: 22.222222 | AZ23: 317.26943 | BA23: 296.60753 | BB23: 20.661899 | BC23: 6.5124139 | BD23: 45.661904 | BE23: 50.061427 | BF23: 24.719021 | BG23: 50 | BH23: 13.333333 | BI23: 100 | BJ23: NA | BK23: NA | BL23: NA | BM23: NA | BN23: NA | BO23: 20 | BP23: 1.3345071 | BQ23: 100 | BR23: NA | BS23: NA | BT23: NA | BU23: NA | BV23: NA | BW23: 20 | BX23: 150 | BY23: 10 | BZ23: 0 | CA23: 0 | CB23: 0 | CC23: 0 | CD23: 0 | CE23: 10 | CF23: 130 | CG23: 0 | CH23: 0 | CI23: 0 | CJ23: 0 | CK23: 0 | CL23: 0 | CM23: 10 | CN23: 20 | CO23: 10 | CP23: 0 | CQ23: 0 | CR23: 0 | CS23: 0 | CT23: 0 | CU23: 17.937097 | CV23: 286.07556 | CW23: 13.256781 | CX23: 0 | CY23: 0 | CZ23: 0 | DA23: 0 | DB23: 0 | DC23: 14.349677 | DD23: 282.25786 | DE23: 0 | DF23: 0 | DG23: 0 | DH23: 0 | DI23: 0 | DJ23: 0 | DK23: 3.5874193 | DL23: 3.8176986 | DM23: 13.256781 | DN23: 0 | DO23: 0 | DP23: 0 | DQ23: 0 | DR23: 0 | DS23: 32.57146 | DT23: 47.497516 | DU23: 39.6 | DV23: NA | DW23: NA | DX23: NA | DY23: NA | DZ23: NA | EA23: 41.2 | EB23: 50.678937 | EC23: NA | ED23: NA | EE23: NA | EF23: NA | EG23: NA | EH23: NA | EI23: 20.6 | EJ23: 15.026643 | EK23: 39.6 | EL23: NA | EM23: NA | EN23: NA | EO23: NA | EP23: NA | EQ23: 10 | ER23: 0 | ES23: 10 | ET23: 13.256781 | EU23: 0 | EV23: 13.256781 | EW23: 100 | EX23: 100 | EY23: 39.6 | EZ23: NA | FA23: 39.6 | FB23: 11.111111 | FC23: 33.333333 | FD23: 90 | FE23: 90 | FF23: 0 | FG23: 0 | FH23: 0 | FI23: NA | FJ23: 41.2 | FK23: 50.678937 | FL23: NA | FM23: NA | FN23: NA | FO23: NA | FP23: NA | FQ23: NA | FR23: 38.888889 | FS23: 83.333333 | FT23: 0 | FU23: 0
